<?xml version="1.0" ?>
<!-- =================================================================================== -->
<!-- |    This document was autogenerated by xacro from piper_h_description.xacro      | -->
<!-- |    EDITING THIS FILE BY HAND IS NOT RECOMMENDED                                 | -->
<!-- =================================================================================== -->
<!-- This URDF was automatically created by SolidWorks to URDF Exporter! Originally created by Stephen Brawner (brawner@gmail.com) 
     Commit Version: 1.6.0-4-g7f85cfe  Build Version: 1.6.7995.38578
     For more information, please see http://wiki.ros.org/sw_urdf_exporter -->
<robot name="piper_l_camera">
  <material name="aluminum">
    <color rgba="0.5 0.5 0.5 1"/>
  </material>
  <material name="plastic">
    <color rgba="0.1 0.1 0.1 1"/>
  </material>
  <link name="d435_camera_link"/>
  <!-- camera body, with origin at bottom screw mount -->
  <joint name="camera_joint" type="fixed">
    <origin rpy="0 0 0" xyz="0 0 0"/>
    <parent link="d435_camera_link"/>
    <child link="camera_bottom_screw_frame"/>
  </joint>
  <link name="camera_bottom_screw_frame"/>
  <joint name="camera_link_joint" type="fixed">
    <origin rpy="0 0 0" xyz="0.010600000000000002 0.0175 0.0125"/>
    <parent link="camera_bottom_screw_frame"/>
    <child link="camera_link"/>
  </joint>
  <link name="camera_link">
    <visual>
      <!-- the mesh origin is at front plate in between the two infrared camera axes -->
      <origin rpy="1.5707963267948966 0 1.5707963267948966" xyz="0.0043 -0.0175 0"/>
      <geometry>
        <mesh filename="package://realsense2_description/meshes/d435.dae"/>
      </geometry>
    </visual>
    <collision>
      <origin rpy="0 0 0" xyz="0 -0.0175 0"/>
      <geometry>
        <box size="0.02505 0.09 0.025"/>
      </geometry>
    </collision>
    <inertial>
      <!-- The following are not reliable values, and should not be used for modeling -->
      <mass value="0.072"/>
      <origin xyz="0 0 0"/>
      <inertia ixx="0.003881243" ixy="0.0" ixz="0.0" iyy="0.000498940" iyz="0.0" izz="0.003879257"/>
    </inertial>
  </link>
  <!-- <xacro:if value="${add_plug}">
      <xacro:usb_plug parent="${name}_link" name="${name}_usb_plug">
        <origin xyz="${d435_cam_mount_from_center_offset - 0.02095} ${-d435_cam_depth_py - 0.0353} 0" rpy="0 0 0"/>
      </xacro:usb_plug>
    </xacro:if> -->
  <link name="base_link">
    <inertial>
      <origin rpy="0 0 0" xyz="-0.0116216679858881 4.15788440943184E-05 0.0410845423187343"/>
      <mass value="0.17076936349368"/>
      <inertia ixx="0.000228123208400866" ixy="1.38955464051488E-07" ixz="6.65141446336986E-06" iyy="0.00027812842789125" iyz="1.65175257145242E-07" izz="0.000229266732859796"/>
    </inertial>
    <visual>
      <origin rpy="0 0 0" xyz="0 0 0"/>
      <geometry>
        <mesh filename="package://piper_h_description/meshes/dark_dae/base_link.dae"/>
      </geometry>
    </visual>
    <collision>
      <origin rpy="0 0 0" xyz="0 0 0"/>
      <geometry>
        <mesh filename="package://piper_h_description/meshes/dark_dae/base_link.dae"/>
      </geometry>
    </collision>
  </link>
  <link name="Link1">
    <inertial>
      <origin rpy="0 0 0" xyz="0.000898972809391425 -0.0017128345134696 -0.00895795324198079"/>
      <mass value="0.095130320813071"/>
      <inertia ixx="3.89303819225542E-05" ixy="2.71827364740144E-07" ixz="1.78296584027163E-07" iyy="5.60153481205046E-05" iyz="1.02032883575856E-07" izz="4.65461363833488E-05"/>
    </inertial>
    <visual>
      <origin rpy="0 0 0" xyz="0 0 0"/>
      <geometry>
        <mesh filename="package://piper_h_description/meshes/dark_dae/link1.dae"/>
      </geometry>
    </visual>
    <collision>
      <origin rpy="0 0 0" xyz="0 0 0"/>
      <geometry>
        <mesh filename="package://piper_h_description/meshes/dark_dae/link1.dae"/>
      </geometry>
    </collision>
  </link>
  <joint name="joint1" type="revolute">
    <origin rpy="0 0 0" xyz="0 0 0.123"/>
    <parent link="base_link"/>
    <child link="Link1"/>
    <axis xyz="0 0 1"/>
    <limit effort="100" lower="-2.618" upper="2.618" velocity="3"/>
  </joint>
  <link name="Link2">
    <inertial>
      <origin rpy="0 0 0" xyz="0.175058051795962 -0.013263959401964 0.00160398731659567"/>
      <mass value="0.297349969020434"/>
      <inertia ixx="0.000164919085428283" ixy="6.39135842640096E-05" ixz="-1.43495991521534E-06" iyy="0.00163150429985587" iyz="-1.15776231590507E-06" izz="0.00168482164179664"/>
    </inertial>
    <visual>
      <origin rpy="0 0 0" xyz="0 0 0"/>
      <geometry>
        <mesh filename="package://piper_h_description/meshes/dark_dae/link2.dae"/>
      </geometry>
    </visual>
    <collision>
      <origin rpy="0 0 0" xyz="0 0 0"/>
      <geometry>
        <mesh filename="package://piper_h_description/meshes/dark_dae/link2.dae"/>
      </geometry>
    </collision>
  </link>
  <joint name="joint2" type="revolute">
    <origin rpy="1.5708 -0.13674 3.1416" xyz="0 0 0"/>
    <parent link="Link1"/>
    <child link="Link2"/>
    <axis xyz="0 0 1"/>
    <limit effort="100" lower="0" upper="3.14" velocity="3"/>
  </joint>
  <link name="Link3">
    <inertial>
      <origin rpy="0 0 0" xyz="-0.00937198976084005 -0.116255702062803 -0.000655711046030733"/>
      <mass value="0.139005088174055"/>
      <inertia ixx="0.000138596904431255" ixy="-3.43992762936895E-07" ixz="3.78558835970272E-07" iyy="4.71404976476514E-05" iyz="9.97047138050079E-07" izz="0.000149219114996657"/>
    </inertial>
    <visual>
      <origin rpy="0 0 0" xyz="0 0 0"/>
      <geometry>
        <mesh filename="package://piper_h_description/meshes/dark_dae/link3.dae"/>
      </geometry>
    </visual>
    <collision>
      <origin rpy="0 0 0" xyz="0 0 0"/>
      <geometry>
        <mesh filename="package://piper_h_description/meshes/dark_dae/link3.dae"/>
      </geometry>
    </collision>
  </link>
  <joint name="joint3" type="revolute">
    <origin rpy="0 0 -1.8796" xyz="0.28508 0 0"/>
    <parent link="Link2"/>
    <child link="Link3"/>
    <axis xyz="0 0 1"/>
    <limit effort="100" lower="-2.697" upper="0" velocity="3"/>
  </joint>
  <link name="Link4">
    <inertial>
      <origin rpy="0 0 0" xyz="0.00120008498546645 0.00402105386550108 -0.00901261181081513"/>
      <mass value="0.0625155037542606"/>
      <inertia ixx="4.34001804299788E-05" ixy="-1.78247237961623E-07" ixz="7.9877981542642E-07" iyy="3.77270563878061E-05" iyz="3.92168392419924E-07" izz="3.65881057070137E-05"/>
    </inertial>
    <visual>
      <origin rpy="0 0 0" xyz="0 0 0"/>
      <geometry>
        <mesh filename="package://piper_h_description/meshes/dark_dae/link4.dae"/>
      </geometry>
    </visual>
    <collision>
      <origin rpy="0 0 0" xyz="0 0 0"/>
      <geometry>
        <mesh filename="package://piper_h_description/meshes/dark_dae/link4.dae"/>
      </geometry>
    </collision>
  </link>
  <joint name="joint4" type="revolute">
    <origin rpy="1.5708 0 0.17203" xyz="0 -0.25666 0"/>
    <parent link="Link3"/>
    <child link="Link4"/>
    <axis xyz="-0.087161 0 0.99619"/>
    <limit effort="100" lower="-1.832" upper="1.832" velocity="3"/>
  </joint>
  <link name="Link5">
    <inertial>
      <origin rpy="0 0 0" xyz="-9.76421424187524E-05 -0.0495078447416577 -0.0069183293653338"/>
      <mass value="0.0683301439531726"/>
      <inertia ixx="8.08932317895225E-05" ixy="2.20176838731191E-07" ixz="5.56694167592644E-08" iyy="4.13226227161016E-05" iyz="1.71025553076376E-05" izz="7.62573282419664E-05"/>
    </inertial>
    <visual>
      <origin rpy="0 0 0" xyz="0 0 0"/>
      <geometry>
        <mesh filename="package://piper_h_description/meshes/dark_dae/link5.dae"/>
      </geometry>
    </visual>
    <collision>
      <origin rpy="0 0 0" xyz="0 0 0"/>
      <geometry>
        <mesh filename="package://piper_h_description/meshes/dark_dae/link5.dae"/>
      </geometry>
    </collision>
  </link>
  <joint name="joint5" type="revolute">
    <origin rpy="-1.5708 -0.087272 0" xyz="0 0 0"/>
    <parent link="Link4"/>
    <child link="Link5"/>
    <axis xyz="0 0 -1"/>
    <limit effort="100" lower="-1.22" upper="1.22" velocity="3"/>
  </joint>
  <link name="Link6">
    <inertial>
      <origin rpy="0 0 0" xyz="0.0769862132705599 0.0288041655584747 -0.162335527696906"/>
      <mass value="0.851169543242842"/>
      <inertia ixx="0.00204979841659076" ixy="-3.46794622727557E-05" ixz="-0.000104197916276416" iyy="0.00210041391526329" iyz="-0.000112551398932383" izz="0.000469888685422321"/>
    </inertial>
    <visual>
      <origin rpy="-1.57 0 1.57" xyz="0.008 -0.002 0.064"/>
      <geometry>
        <mesh filename="package://piper_h_description/meshes/dae/gripper_base_100_v3.dae"/>
      </geometry>
    </visual>
    <collision>
      <origin rpy="-1.57 0 1.57" xyz="0.008 -0.002 0.064"/>
      <geometry>
        <mesh filename="package://piper_h_description/meshes/dae/gripper_base_100_v3.dae"/>
      </geometry>
    </collision>
  </link>
  <joint name="joint6" type="revolute">
    <origin rpy="1.5708 0 0.0" xyz="0 -0.096 0"/>
    <parent link="Link5"/>
    <child link="Link6"/>
    <axis xyz="-0.087161 0 0.99619"/>
    <limit effort="100" lower="-3.14" upper="3.14" velocity="3"/>
  </joint>
  <link name="Link7">
    <visual>
      <inertial>
        <origin rpy="0 0 0" xyz="0.000277816920932317 0.0467673824063769 -0.00921030054508036"/>
        <mass value="0.0264822021416248"/>
        <inertia ixx="9.99779119357223E-06" ixy="-1.57542283433504E-07" ixz="2.71367446701359E-08" iyy="6.17952441557932E-06" iyz="1.58939319453383E-06" izz="1.4210192754512E-05"/>
      </inertial>
      <geometry>
        <mesh filename="package://piper_h_description/meshes/dae/link7.dae"/>
      </geometry>
    </visual>
    <collision>
      <geometry>
        <mesh filename="package://piper_h_description/meshes/dae/link7.dae"/>
      </geometry>
    </collision>
  </link>
  <joint name="joint7" type="prismatic">
    <origin rpy="1.5708 0 0" xyz="0 0 0.13503"/>
    <parent link="Link6"/>
    <child link="Link7"/>
    <axis xyz="0 0 -1"/>
    <limit effort="100" lower="0" upper="0.05" velocity="1"/>
  </joint>
  <link name="Link8">
    <inertial>
      <origin rpy="0 0 0" xyz="0.000277816920932317 0.0467673824063769 -0.00921030054508036"/>
      <mass value="0.0264822021416248"/>
      <inertia ixx="9.99779119357223E-06" ixy="-1.57542283433504E-07" ixz="2.71367446701359E-08" iyy="6.17952441557932E-06" iyz="1.58939319453383E-06" izz="1.4210192754512E-05"/>
    </inertial>
    <visual>
      <origin rpy="0 0 0" xyz="0 0 0"/>
      <geometry>
        <mesh filename="package://piper_h_description/meshes/dae/link8.dae"/>
      </geometry>
    </visual>
    <collision>
      <origin rpy="0 0 0" xyz="0 0 0"/>
      <geometry>
        <mesh filename="package://piper_h_description/meshes/dae/link8.dae"/>
      </geometry>
    </collision>
  </link>
  <joint name="joint8" type="prismatic">
    <origin rpy="-1.5708 0 0" xyz="0 0 0.13503"/>
    <parent link="Link6"/>
    <child link="Link8"/>
    <axis xyz="0 0 1"/>
    <limit effort="100" lower="-0.05" upper="0" velocity="1"/>
  </joint>
  <link name="camera_stand_link">
    <inertial>
      <origin rpy="0.0 0.0 0.0" xyz="0.0 0.0 0.0"/>
      <mass value="0.0"/>
      <inertia ixx="0.0" ixy="0.0" ixz="0.0" iyy="0.0" iyz="0.0" izz="0.0"/>
    </inertial>
    <visual name="">
      <origin rpy="0.0 3.14 1.57" xyz="0.0 0.0 0.0"/>
      <geometry>
        <mesh filename="package://piper_h_description/meshes/dae/realsense_mid_stand_v2.dae"/>
      </geometry>
    </visual>
    <collision>
      <origin rpy="0.0 3.14 1.57" xyz="0.0 0.0 0.0"/>
      <geometry>
        <mesh filename="package://piper_h_description/meshes/dae/realsense_mid_stand_v2.dae"/>
      </geometry>
    </collision>
  </link>
  <joint name="camera_stand_joint" type="fixed">
    <origin rpy="0 0 0" xyz="-0.034 -0.002 0.023"/>
    <parent link="Link6"/>
    <child link="camera_stand_link"/>
    <axis xyz="0.0 0.0 0.0"/>
    <limit effort="0.0" lower="0.0" upper="0.0" velocity="0.0"/>
  </joint>
  <joint name="d435_camera_joint" type="fixed">
    <origin rpy="0.0 -1.22 0" xyz="-0.032 -0.028 0.0"/>
    <parent link="camera_stand_link"/>
    <child link="d435_camera_link"/>
    <axis xyz="0.0 0.0 0.0"/>
    <limit effort="0.0" lower="0.0" upper="0.0" velocity="0.0"/>
  </joint>
</robot>
