<?xml version="1.0" ?>
<!-- =================================================================================== -->
<!-- |    This document was autogenerated by xacro from piper_x_description.xacro      | -->
<!-- |    EDITING THIS FILE BY HAND IS NOT RECOMMENDED                                 | -->
<!-- =================================================================================== -->
<!-- This URDF was automatically created by SolidWorks to URDF Exporter! Originally created by Stephen Brawner (brawner@gmail.com) 
     Commit Version: 1.6.0-4-g7f85cfe  Build Version: 1.6.7995.38578
     For more information, please see http://wiki.ros.org/sw_urdf_exporter -->
<robot name="piper_x_camera">
  <material name="aluminum">
    <color rgba="0.5 0.5 0.5 1"/>
  </material>
  <material name="plastic">
    <color rgba="0.1 0.1 0.1 1"/>
  </material>
  <link name="d435_camera_link"/>
  <!-- camera body, with origin at bottom screw mount -->
  <joint name="camera_joint" type="fixed">
    <origin rpy="0 0 0" xyz="0 0 0"/>
    <parent link="d435_camera_link"/>
    <child link="camera_bottom_screw_frame"/>
  </joint>
  <link name="camera_bottom_screw_frame"/>
  <joint name="camera_link_joint" type="fixed">
    <origin rpy="0 0 0" xyz="0.010600000000000002 0.0175 0.0125"/>
    <parent link="camera_bottom_screw_frame"/>
    <child link="camera_link"/>
  </joint>
  <link name="camera_link">
    <visual>
      <!-- the mesh origin is at front plate in between the two infrared camera axes -->
      <origin rpy="1.5707963267948966 0 1.5707963267948966" xyz="0.0043 -0.0175 0"/>
      <geometry>
        <mesh filename="package://realsense2_description/meshes/d435.dae"/>
      </geometry>
    </visual>
    <collision>
      <origin rpy="0 0 0" xyz="0 -0.0175 0"/>
      <geometry>
        <box size="0.02505 0.09 0.025"/>
      </geometry>
    </collision>
    <inertial>
      <!-- The following are not reliable values, and should not be used for modeling -->
      <mass value="0.072"/>
      <origin xyz="0 0 0"/>
      <inertia ixx="0.003881243" ixy="0.0" ixz="0.0" iyy="0.000498940" iyz="0.0" izz="0.003879257"/>
    </inertial>
  </link>
  <!-- <xacro:if value="${add_plug}">
      <xacro:usb_plug parent="${name}_link" name="${name}_usb_plug">
        <origin xyz="${d435_cam_mount_from_center_offset - 0.02095} ${-d435_cam_depth_py - 0.0353} 0" rpy="0 0 0"/>
      </xacro:usb_plug>
    </xacro:if> -->
  <link name="base_link">
    <inertial>
      <origin rpy="0 0 0" xyz="-0.0085443 4.8839E-05 0.044762"/>
      <mass value="0.47421"/>
      <inertia ixx="0.00044509" ixy="5.5896E-07" ixz="1.9736E-05" iyy="0.00049109" iyz="7.1578E-07" izz="0.00055319"/>
    </inertial>
    <visual>
      <origin rpy="0 0 0" xyz="0 0 0"/>
      <geometry>
        <mesh filename="package://piper_x_description/meshes/dae/base_Link.dae"/>
      </geometry>
      <material name="">
        <color rgba="0.59216 0.61961 0.65098 1"/>
      </material>
    </visual>
    <collision>
      <origin rpy="0 0 0" xyz="0 0 0"/>
      <geometry>
        <mesh filename="package://piper_x_description/meshes/dae/base_Link.dae"/>
      </geometry>
    </collision>
  </link>
  <link name="Link1">
    <inertial>
      <origin rpy="0 0 0" xyz="0.0011378 -0.0021698 -0.014112"/>
      <mass value="0.16975"/>
      <inertia ixx="6.466E-05" ixy="7.2374E-07" ixz="5.1556E-08" iyy="8.8951E-05" iyz="1.0827E-07" izz="8.3142E-05"/>
    </inertial>
    <visual>
      <origin rpy="0 0 0" xyz="0 0 0"/>
      <geometry>
        <mesh filename="package://piper_x_description/meshes/dae/J1.dae"/>
      </geometry>
      <material name="">
        <color rgba="0.59216 0.61961 0.65098 1"/>
      </material>
    </visual>
    <collision>
      <origin rpy="0 0 0" xyz="0 0 0"/>
      <geometry>
        <mesh filename="package://piper_x_description/meshes/dae/J1.dae"/>
      </geometry>
    </collision>
  </link>
  <joint name="joint1" type="revolute">
    <origin rpy="0 0 0" xyz="0 0 0.123"/>
    <parent link="base_link"/>
    <child link="Link1"/>
    <axis xyz="0 0 1"/>
    <limit effort="100" lower="-2.618" upper="2.618" velocity="10"/>
  </joint>
  <link name="Link2">
    <inertial>
      <origin rpy="0 0 0" xyz="0.21036 -0.01651 0.0015283"/>
      <mass value="0.37783"/>
      <inertia ixx="0.00022199" ixy="3.2631E-05" ixz="-6.2643E-06" iyy="0.0019854" iyz="-3.0109E-06" izz="0.0020664"/>
    </inertial>
    <visual>
      <origin rpy="0 0 0" xyz="0 0 0"/>
      <geometry>
        <mesh filename="package://piper_x_description/meshes/dae/J2.dae"/>
      </geometry>
    </visual>
    <collision>
      <origin rpy="0 0 0" xyz="0 0 0"/>
      <geometry>
        <mesh filename="package://piper_x_description/meshes/dae/J2.dae"/>
      </geometry>
    </collision>
  </link>
  <joint name="joint2" type="revolute">
    <origin rpy="1.5708 -0.13586 3.1416" xyz="0 0 0"/>
    <parent link="Link1"/>
    <child link="Link2"/>
    <axis xyz="0 0 1"/>
    <limit effort="100" lower="0" upper="3.14" velocity="10"/>
  </joint>
  <link name="Link3">
    <inertial>
      <origin rpy="0 0 0" xyz="0.15119 -0.0060622 0.0013657"/>
      <mass value="0.28003"/>
      <inertia ixx="9.0698E-05" ixy="8.6875E-07" ixz="-2.0769E-06" iyy="0.00035668" iyz="1.1019E-06" izz="0.00039114"/>
    </inertial>
    <visual>
      <origin rpy="0 0 0" xyz="0 0 0"/>
      <geometry>
        <mesh filename="package://piper_x_description/meshes/dae/J3.dae"/>
      </geometry>
      <material name="">
        <color rgba="0.59216 0.61961 0.65098 1"/>
      </material>
    </visual>
    <collision>
      <origin rpy="0 0 0" xyz="0 0 0"/>
      <geometry>
        <mesh filename="package://piper_x_description/meshes/dae/J3.dae"/>
      </geometry>
    </collision>
  </link>
  <joint name="joint3" type="revolute">
    <origin rpy="0 0 2.8377" xyz="0.28503 0 0"/>
    <parent link="Link2"/>
    <child link="Link3"/>
    <axis xyz="0 0 1"/>
    <limit effort="100" lower="-2.9671" upper="0" velocity="10"/>
  </joint>
  <link name="Link4">
    <inertial>
      <origin rpy="0 0 0" xyz="0.041795 -0.032887 -0.0088781"/>
      <mass value="0.1211"/>
      <inertia ixx="5.6173E-05" ixy="-8.0853E-07" ixz="-5.604E-07" iyy="6.2662E-05" iyz="-1.3477E-07" izz="6.8648E-05"/>
    </inertial>
    <visual>
      <origin rpy="0 0 0" xyz="0 0 0"/>
      <geometry>
        <mesh filename="package://piper_x_description/meshes/dae/J4.dae"/>
      </geometry>
      <material name="">
        <color rgba="0.69804 0.69804 0.69804 0.875"/>
      </material>
    </visual>
    <collision>
      <origin rpy="0 0 0" xyz="0 0 0"/>
      <geometry>
        <mesh filename="package://piper_x_description/meshes/dae/J4.dae"/>
      </geometry>
    </collision>
  </link>
  <joint name="joint4" type="revolute">
    <origin rpy="0 0 0.075129" xyz="0.27264 0 0"/>
    <parent link="Link3"/>
    <child link="Link4"/>
    <axis xyz="0 0 1"/>
    <limit effort="100" lower="-1.57" upper="1.57" velocity="10"/>
  </joint>
  <link name="Link5">
    <inertial>
      <origin rpy="0 0 0" xyz="0.0041507 0.00024807 -0.015852"/>
      <mass value="0.094498"/>
      <inertia ixx="4.0846E-05" ixy="5.2625E-08" ixz="7.7998E-07" iyy="2.5458E-05" iyz="-2.0306E-07" izz="3.3445E-05"/>
    </inertial>
    <visual>
      <origin rpy="0 0 0" xyz="0 0 0"/>
      <geometry>
        <mesh filename="package://piper_x_description/meshes/dae/J5.dae"/>
      </geometry>
      <material name="">
        <color rgba="0.59216 0.61961 0.65098 1"/>
      </material>
    </visual>
    <collision>
      <origin rpy="0 0 0" xyz="0 0 0"/>
      <geometry>
        <mesh filename="package://piper_x_description/meshes/dae/J5.dae"/>
      </geometry>
    </collision>
  </link>
  <joint name="joint5" type="revolute">
    <origin rpy="-1.5708 0 0" xyz="0.076857 0.00062395 0"/>
    <parent link="Link4"/>
    <child link="Link5"/>
    <axis xyz="0 0 1"/>
    <limit effort="100" lower="-1.57" upper="1.57" velocity="10"/>
  </joint>
  <link name="Link6">
    <inertial>
      <origin rpy="0 0 0" xyz="4.4377E-07 -1.9614E-05 0.031556"/>
      <mass value="0.0061311"/>
      <inertia ixx="5.1682E-07" ixy="9.18E-25" ixz="1.1291E-22" iyy="5.1683E-07" iyz="2.6088E-09" izz="9.833E-07"/>
    </inertial>
    <visual>
      <origin rpy="-1.57 0 3.14" xyz="0.002 0.0078 0.06"/>
      <geometry>
        <mesh filename="package://piper_x_description/meshes/dae/gripper_base_100_v2.dae" scale="0.8 0.8 0.8"/>
      </geometry>
      <material name="">
        <color rgba="1 1 1 1"/>
      </material>
    </visual>
    <collision>
      <origin rpy="-1.57 0 3.14" xyz="0.002 0.0078 0.06"/>
      <geometry>
        <mesh filename="package://piper_x_description/meshes/dae/gripper_base_100_v2.dae" scale="0.8 0.8 0.8"/>
      </geometry>
    </collision>
  </link>
  <joint name="joint6" type="revolute">
    <origin rpy="1.5708 0 1.5708" xyz="0.035 0 0"/>
    <parent link="Link5"/>
    <child link="Link6"/>
    <axis xyz="0 0 1"/>
    <limit effort="100" lower="-3.14" upper="3.14" velocity="10"/>
  </joint>
  <link name="Link7">
    <inertial>
      <origin rpy="0 0 0" xyz="0.000277816920932317 0.0467673824063769 -0.00921030054508036"/>
      <mass value="0.0264822021416248"/>
      <inertia ixx="9.99779119357223E-06" ixy="-1.57542283433504E-07" ixz="2.71367446701359E-08" iyy="6.17952441557932E-06" iyz="1.58939319453383E-06" izz="1.4210192754512E-05"/>
    </inertial>
    <visual>
      <geometry>
        <mesh filename="package://piper_x_description/meshes/dae/J7.dae"/>
      </geometry>
      <material name="LightGrey">
        <color rgba="0.7 0.7 0.7 1.0"/>
      </material>
    </visual>
    <collision>
      <geometry>
        <mesh filename="package://piper_x_description/meshes/dae/J7.dae"/>
      </geometry>
    </collision>
  </link>
  <joint name="joint7" type="prismatic">
    <origin rpy="1.5708 0 1.5708" xyz="0 0 0.13503"/>
    <parent link="Link6"/>
    <child link="Link7"/>
    <axis xyz="0 0 -1"/>
    <limit effort="100" lower="0" upper="0.05" velocity="1"/>
  </joint>
  <link name="Link8">
    <inertial>
      <origin rpy="0 0 0" xyz="0.000277816920932317 0.0467673824063769 -0.00921030054508036"/>
      <mass value="0.0264822021416248"/>
      <inertia ixx="9.99779119357223E-06" ixy="-1.57542283433504E-07" ixz="2.71367446701359E-08" iyy="6.17952441557932E-06" iyz="1.58939319453383E-06" izz="1.4210192754512E-05"/>
    </inertial>
    <visual>
      <origin rpy="0 0 0" xyz="0 0 0"/>
      <geometry>
        <mesh filename="package://piper_x_description/meshes/dae/J8.dae"/>
      </geometry>
      <material name="">
        <color rgba="0.792156862745098 0.819607843137255 0.933333333333333 1"/>
      </material>
    </visual>
    <collision>
      <origin rpy="0 0 0" xyz="0 0 0"/>
      <geometry>
        <mesh filename="package://piper_x_description/meshes/dae/J8.dae"/>
      </geometry>
    </collision>
  </link>
  <joint name="joint8" type="prismatic">
    <origin rpy="-1.5708 0 1.5708" xyz="0 0 0.13503"/>
    <parent link="Link6"/>
    <child link="Link8"/>
    <axis xyz="0 0 1"/>
    <limit effort="100" lower="-0.05" upper="0" velocity="1"/>
  </joint>
  <link name="camera_stand_link">
    <inertial>
      <origin rpy="0.0 0.0 0.0" xyz="0.0 0.0 0.0"/>
      <mass value="0.0"/>
      <inertia ixx="0.0" ixy="0.0" ixz="0.0" iyy="0.0" iyz="0.0" izz="0.0"/>
    </inertial>
    <visual name="">
      <origin rpy="0.0 0.0 0.0" xyz="0.0 0.0 0.0"/>
      <geometry>
        <mesh filename="package://piper_description/meshes/dae/realsense_mid_stand.dae"/>
      </geometry>
    </visual>
    <collision>
      <origin rpy="0.0 0.0 0.0" xyz="0.0 0.0 0.0"/>
      <geometry>
        <mesh filename="package://piper_description/meshes/dae/realsense_mid_stand.dae"/>
      </geometry>
    </collision>
  </link>
  <joint name="camera_stand_joint" type="fixed">
    <origin rpy="1.57 3.14 0.0" xyz="0.001 -0.036 0.022"/>
    <parent link="Link6"/>
    <child link="camera_stand_link"/>
    <axis xyz="0.0 0.0 0.0"/>
    <limit effort="0.0" lower="0.0" upper="0.0" velocity="0.0"/>
  </joint>
  <joint name="d435_camera_joint" type="fixed">
    <origin rpy="0.0 -1.22 1.57" xyz="0.029 -0.069 0.022"/>
    <parent link="Link6"/>
    <child link="d435_camera_link"/>
    <axis xyz="0.0 0.0 0.0"/>
    <limit effort="0.0" lower="0.0" upper="0.0" velocity="0.0"/>
  </joint>
</robot>
