<?xml version="1.0" ?>
<!-- =================================================================================== -->
<!-- |    This document was autogenerated by xacro from piper_l_description.xacro      | -->
<!-- |    EDITING THIS FILE BY HAND IS NOT RECOMMENDED                                 | -->
<!-- =================================================================================== -->
<!-- This URDF was automatically created by SolidWorks to URDF Exporter! Originally created by Stephen Brawner (brawner@gmail.com) 
     Commit Version: 1.6.0-4-g7f85cfe  Build Version: 1.6.7995.38578
     For more information, please see http://wiki.ros.org/sw_urdf_exporter -->
<robot name="piper_l_camera">
  <material name="aluminum">
    <color rgba="0.5 0.5 0.5 1"/>
  </material>
  <material name="plastic">
    <color rgba="0.1 0.1 0.1 1"/>
  </material>
  <link name="d435_camera_link"/>
  <!-- camera body, with origin at bottom screw mount -->
  <joint name="camera_joint" type="fixed">
    <origin rpy="0 0 0" xyz="0 0 0"/>
    <parent link="d435_camera_link"/>
    <child link="camera_bottom_screw_frame"/>
  </joint>
  <link name="camera_bottom_screw_frame"/>
  <joint name="camera_link_joint" type="fixed">
    <origin rpy="0 0 0" xyz="0.010600000000000002 0.0175 0.0125"/>
    <parent link="camera_bottom_screw_frame"/>
    <child link="camera_link"/>
  </joint>
  <link name="camera_link">
    <visual>
      <!-- the mesh origin is at front plate in between the two infrared camera axes -->
      <origin rpy="1.5707963267948966 0 1.5707963267948966" xyz="0.0043 -0.0175 0"/>
      <geometry>
        <mesh filename="package://realsense2_description/meshes/d435.dae"/>
      </geometry>
    </visual>
    <collision>
      <origin rpy="0 0 0" xyz="0 -0.0175 0"/>
      <geometry>
        <box size="0.02505 0.09 0.025"/>
      </geometry>
    </collision>
    <inertial>
      <!-- The following are not reliable values, and should not be used for modeling -->
      <mass value="0.072"/>
      <origin xyz="0 0 0"/>
      <inertia ixx="0.003881243" ixy="0.0" ixz="0.0" iyy="0.000498940" iyz="0.0" izz="0.003879257"/>
    </inertial>
  </link>
  <!-- <xacro:if value="${add_plug}">
      <xacro:usb_plug parent="${name}_link" name="${name}_usb_plug">
        <origin xyz="${d435_cam_mount_from_center_offset - 0.02095} ${-d435_cam_depth_py - 0.0353} 0" rpy="0 0 0"/>
      </xacro:usb_plug>
    </xacro:if> -->
  <link name="base_link">
    <inertial>
      <origin rpy="0 0 0" xyz="-0.00868903062596066 -7.81380379250471E-05 0.0446229676471226"/>
      <mass value="0.228506683240186"/>
      <inertia ixx="0.000187231110737863" ixy="-1.08010529187549E-07" ixz="7.71183528612253E-06" iyy="0.000204010911651774" iyz="1.70367399031094E-07" izz="0.00023064619033588"/>
    </inertial>
    <visual>
      <origin rpy="0 0 0" xyz="0 0 0"/>
      <geometry>
        <mesh filename="package://piper_l_description/meshes/dark_dae/base_link.dae"/>
      </geometry>
    </visual>
    <collision>
      <origin rpy="0 0 0" xyz="0 0 0"/>
      <geometry>
        <mesh filename="package://piper_l_description/meshes/dark_dae/base_link.dae"/>
      </geometry>
    </collision>
  </link>
  <link name="Link1">
    <inertial>
      <origin rpy="0 0 0" xyz="0.000817078696798893 0.00114472671573105 -0.00814265146610774"/>
      <mass value="0.104656591084326"/>
      <inertia ixx="3.99694684501781E-05" ixy="2.71846206160129E-07" ixz="1.78275886199695E-07" iyy="5.78589658643876E-05" iyz="1.01977672018063E-07" izz="4.75851844139222E-05"/>
    </inertial>
    <visual>
      <origin rpy="0 0 0" xyz="0 0 0"/>
      <geometry>
        <mesh filename="package://piper_l_description/meshes/dark_dae/link1.dae"/>
      </geometry>
    </visual>
    <collision>
      <origin rpy="0 0 0" xyz="0 0 0"/>
      <geometry>
        <mesh filename="package://piper_l_description/meshes/dark_dae/link1.dae"/>
      </geometry>
    </collision>
  </link>
  <joint name="joint1" type="revolute">
    <origin rpy="0 0 0" xyz="0 0 0.123"/>
    <parent link="base_link"/>
    <child link="Link1"/>
    <axis xyz="0 0 1"/>
    <limit effort="100" lower="-2.618" upper="2.618" velocity="3"/>
  </joint>
  <link name="Link2">
    <inertial>
      <origin rpy="0 0 0" xyz="0.214411452554835 -0.0136807991474291 0.00265923105206891"/>
      <mass value="0.289829779851577"/>
      <inertia ixx="0.000159609737372076" ixy="8.49438511625834E-05" ixz="-8.73341391348404E-07" iyy="0.00182424524515505" iyz="-1.7222217649261E-06" izz="0.00188778950006189"/>
    </inertial>
    <visual>
      <origin rpy="0 0 0" xyz="0 0 0"/>
      <geometry>
        <mesh filename="package://piper_l_description/meshes/dark_dae/link2.dae"/>
      </geometry>
    </visual>
    <collision>
      <origin rpy="0 0 0" xyz="0 0 0"/>
      <geometry>
        <mesh filename="package://piper_l_description/meshes/dark_dae/link2.dae"/>
      </geometry>
    </collision>
  </link>
  <joint name="joint2" type="revolute">
    <origin rpy="1.5708 -0.10598 3.1416" xyz="0 0 0"/>
    <parent link="Link1"/>
    <child link="Link2"/>
    <axis xyz="0 0 1"/>
    <limit effort="100" lower="0" upper="3.14" velocity="3"/>
  </joint>
  <link name="Link3">
    <inertial>
      <origin rpy="0 0 0" xyz="-0.00911397384332024 -0.149791842909887 -0.000591510024110218"/>
      <mass value="0.144963320053385"/>
      <inertia ixx="0.000284000764414434" ixy="6.61776597268393E-06" ixz="3.88642213881568E-07" iyy="4.88134965842348E-05" iyz="8.80027301936097E-07" izz="0.000297733639002112"/>
    </inertial>
    <visual>
      <origin rpy="0 0 0" xyz="0 0 0"/>
      <geometry>
        <mesh filename="package://piper_l_description/meshes/dark_dae/link3.dae"/>
      </geometry>
    </visual>
    <collision>
      <origin rpy="0 0 0" xyz="0 0 0"/>
      <geometry>
        <mesh filename="package://piper_l_description/meshes/dark_dae/link3.dae"/>
      </geometry>
    </collision>
  </link>
  <joint name="joint3" type="revolute">
    <origin rpy="0 0 -1.8325" xyz="0.33823 0 0"/>
    <parent link="Link2"/>
    <child link="Link3"/>
    <axis xyz="0 0 1"/>
    <limit effort="100" lower="-2.697" upper="0" velocity="3"/>
  </joint>
  <link name="Link4">
    <inertial>
      <origin rpy="0 0 0" xyz="0.0010653905699945 0.00476990191039629 -0.00995810184233214"/>
      <mass value="0.063036548689954"/>
      <inertia ixx="1.68358640686144E-05" ixy="-1.51073528999065E-08" ixz="-3.61196055919328E-07" iyy="2.79335598814104E-05" iyz="1.18113194001076E-07" izz="1.85339684805634E-05"/>
    </inertial>
    <visual>
      <origin rpy="0 0 0" xyz="0 0 0"/>
      <geometry>
        <mesh filename="package://piper_l_description/meshes/dark_dae/link4.dae"/>
      </geometry>
    </visual>
    <collision>
      <origin rpy="0 0 0" xyz="0 0 0"/>
      <geometry>
        <mesh filename="package://piper_l_description/meshes/dark_dae/link4.dae"/>
      </geometry>
    </collision>
  </link>
  <joint name="joint4" type="revolute">
    <origin rpy="1.5708 0 0.1557" xyz="0 -0.3215 0"/>
    <parent link="Link3"/>
    <child link="Link4"/>
    <axis xyz="0 0 1"/>
    <limit effort="100" lower="-1.832" upper="1.832" velocity="3"/>
  </joint>
  <link name="Link5">
    <inertial>
      <origin rpy="0 0 0" xyz="-5.62618579153795E-05 -0.0453229588602131 -0.00689048082401968"/>
      <mass value="0.069099989781007"/>
      <inertia ixx="1.94244470320096E-05" ixy="-3.01270043465718E-08" ixz="-1.82908713601451E-08" iyy="2.97665185121334E-05" iyz="1.74803886281955E-07" izz="2.43073597160068E-05"/>
    </inertial>
    <visual>
      <origin rpy="0 0 0" xyz="0 0 0"/>
      <geometry>
        <mesh filename="package://piper_l_description/meshes/dark_dae/link5.dae"/>
      </geometry>
    </visual>
    <collision>
      <origin rpy="0 0 0" xyz="0 0 0"/>
      <geometry>
        <mesh filename="package://piper_l_description/meshes/dark_dae/link5.dae"/>
      </geometry>
    </collision>
  </link>
  <joint name="joint5" type="revolute">
    <origin rpy="-1.5708 -0.087272 0" xyz="0 0 0"/>
    <parent link="Link4"/>
    <child link="Link5"/>
    <axis xyz="0 0 -1"/>
    <limit effort="100" lower="-1.22" upper="1.22" velocity="3"/>
  </joint>
  <link name="Link6">
    <inertial>
      <origin rpy="0 0 0" xyz="-3.49720252756924E-15 -3.47851379593264E-06 -0.00315807577104896"/>
      <mass value="0.00563228459599247"/>
      <inertia ixx="5.13060019382932E-07" ixy="-1.55709158367416E-20" ixz="1.27617424904681E-19" iyy="5.13060019383189E-07" iyz="6.20132760426175E-20" izz="9.81761489300716E-07"/>
    </inertial>
    <visual>
      <origin rpy="-1.57 0 1.57" xyz="0.008 -0.002 0.064"/>
      <geometry>
        <mesh filename="package://piper_l_description/meshes/dae/gripper_base_100_v3.dae" scale="1 1 1"/>
      </geometry>
    </visual>
    <collision>
      <origin rpy="-1.57 0 1.57" xyz="0.008 -0.002 0.064"/>
      <geometry>
        <mesh filename="package://piper_l_description/meshes/dae/gripper_base_100_v3.dae" scale="1 1 1"/>
      </geometry>
    </collision>
  </link>
  <joint name="joint6" type="revolute">
    <origin rpy="1.5708 0 0" xyz="0 -0.091 0"/>
    <parent link="Link5"/>
    <child link="Link6"/>
    <axis xyz="0 0 1"/>
    <limit effort="100" lower="-3.14" upper="3.14" velocity="3"/>
  </joint>
  <link name="Link7">
    <visual>
      <geometry>
        <mesh filename="package://piper_l_description/meshes/dae/link7.dae"/>
      </geometry>
    </visual>
    <collision>
      <geometry>
        <mesh filename="package://piper_l_description/meshes/dae/link7.dae"/>
      </geometry>
    </collision>
    <inertial>
      <mass value="0.0"/>
      <origin rpy="0.0 0.0 0.0" xyz="0.0 0.0 0.0"/>
      <inertia ixx="0.0" ixy="0.0" ixz="0.0" iyy="0.0" iyz="0.0" izz="0.0"/>
    </inertial>
  </link>
  <joint name="joint7" type="prismatic">
    <origin rpy="1.5708 0 0" xyz="0 0 0.13503"/>
    <parent link="Link6"/>
    <child link="Link7"/>
    <axis xyz="0 0 -1"/>
    <limit effort="100" lower="0" upper="0.05" velocity="1"/>
  </joint>
  <link name="Link8">
    <inertial>
      <origin rpy="0 0 0" xyz="0.000277816920932317 0.0467673824063769 -0.00921030054508036"/>
      <mass value="0.0264822021416248"/>
      <inertia ixx="9.99779119357223E-06" ixy="-1.57542283433504E-07" ixz="2.71367446701359E-08" iyy="6.17952441557932E-06" iyz="1.58939319453383E-06" izz="1.4210192754512E-05"/>
    </inertial>
    <visual>
      <origin rpy="0 0 0" xyz="0 0 0"/>
      <geometry>
        <mesh filename="package://piper_l_description/meshes/dae/link8.dae"/>
      </geometry>
    </visual>
    <collision>
      <origin rpy="0 0 0" xyz="0 0 0"/>
      <geometry>
        <mesh filename="package://piper_l_description/meshes/dae/link8.dae"/>
      </geometry>
    </collision>
  </link>
  <joint name="joint8" type="prismatic">
    <origin rpy="-1.5708 0 0" xyz="0 0 0.13503"/>
    <parent link="Link6"/>
    <child link="Link8"/>
    <axis xyz="0 0 1"/>
    <limit effort="100" lower="-0.05" upper="0" velocity="1"/>
  </joint>
  <link name="camera_stand_link">
    <inertial>
      <origin rpy="0.0 0.0 0.0" xyz="0.0 0.0 0.0"/>
      <mass value="0.0"/>
      <inertia ixx="0.0" ixy="0.0" ixz="0.0" iyy="0.0" iyz="0.0" izz="0.0"/>
    </inertial>
    <visual name="">
      <origin rpy="0.0 3.14 1.57" xyz="0.0 0.0 0.0"/>
      <geometry>
        <mesh filename="package://piper_l_description/meshes/dae/realsense_mid_stand_v2.dae"/>
      </geometry>
    </visual>
    <collision>
      <origin rpy="0.0 3.14 1.57" xyz="0.0 0.0 0.0"/>
      <geometry>
        <mesh filename="package://piper_l_description/meshes/dae/realsense_mid_stand_v2.dae"/>
      </geometry>
    </collision>
  </link>
  <joint name="camera_stand_joint" type="fixed">
    <origin rpy="0 0 0" xyz="-0.034 -0.002 0.023"/>
    <parent link="Link6"/>
    <child link="camera_stand_link"/>
    <axis xyz="0.0 0.0 0.0"/>
    <limit effort="0.0" lower="0.0" upper="0.0" velocity="0.0"/>
  </joint>
  <joint name="d435_camera_joint" type="fixed">
    <origin rpy="0.0 -1.22 0" xyz="-0.032 -0.028 0.0"/>
    <parent link="camera_stand_link"/>
    <child link="d435_camera_link"/>
    <axis xyz="0.0 0.0 0.0"/>
    <limit effort="0.0" lower="0.0" upper="0.0" velocity="0.0"/>
  </joint>
</robot>
