<?xml version="1.0" encoding="utf-8"?>
<!-- This URDF was automatically created by SolidWorks to URDF Exporter! Originally created by Stephen Brawner (brawner@gmail.com) 
     Commit Version: 1.6.0-4-g7f85cfe  Build Version: 1.6.7995.38578
     For more information, please see http://wiki.ros.org/sw_urdf_exporter -->
<robot
  name="nero_description">
  <link
    name="base_link">
    <inertial>
      <origin
        xyz="-0.00963614954335565 0.00016786624100977 0.044860101664403"
        rpy="0 0 0" />
      <mass
        value="0.487153985946125" />
      <inertia
        ixx="0.000448116331022417"
        ixy="5.78111047127811E-07"
        ixz="1.54743135248644E-05"
        iyy="0.000492511294798627"
        iyz="-4.11935494337721E-07"
        izz="0.000552986424582884" />
    </inertial>
    <visual>
      <origin
        xyz="0 0 0"
        rpy="0 0 0" />
      <geometry>
        <mesh
          filename="package://nero_description/meshes/base_link.STL" />
      </geometry>
      <material
        name="">
        <color
          rgba="0.592156862745098 0.619607843137255 0.650980392156863 1" />
      </material>
    </visual>
    <collision>
      <origin
        xyz="0 0 0"
        rpy="0 0 0" />
      <geometry>
        <mesh
          filename="package://nero_description/meshes/base_link.STL" />
      </geometry>
    </collision>
  </link>
  <link
    name="Link1">
    <inertial>
      <origin
        xyz="0.000715896252246681 0.000898556742748309 -0.0252517626006055"
        rpy="0 0 0" />
      <mass
        value="0.24545463218233" />
      <inertia
        ixx="0.00011319361616663"
        ixy="6.05951634198749E-07"
        ixz="7.40786266784068E-07"
        iyy="0.000125764803621739"
        iyz="3.74212053006065E-07"
        izz="0.000127643109947032" />
    </inertial>
    <visual>
      <origin
        xyz="0 0 0"
        rpy="0 0 0" />
      <geometry>
        <mesh
          filename="package://nero_description/meshes/Link1.STL" />
      </geometry>
      <material
        name="">
        <color
          rgba="0.592156862745098 0.619607843137255 0.650980392156863 1" />
      </material>
    </visual>
    <collision>
      <origin
        xyz="0 0 0"
        rpy="0 0 0" />
      <geometry>
        <mesh
          filename="package://nero_description/meshes/Link1.STL" />
      </geometry>
    </collision>
  </link>
  <joint
    name="joint1"
    type="revolute">
    <origin
      xyz="0 0 0.138"
      rpy="0 0 0" />
    <parent
      link="base_link" />
    <child
      link="Link1" />
    <axis
      xyz="0 0 1" />
    <limit
      lower="-2.7402"
      upper="2.7402"
      effort="100"
      velocity="10" />
  </joint>
  <link
    name="Link2">
    <inertial>
      <origin
        xyz="0.00150006271332911 -0.0864806891090517 0.00233256198231633"
        rpy="0 0 0" />
      <mass
        value="0.340250343180855" />
      <inertia
        ixx="0.00114692547593191"
        ixy="7.82238855198332E-06"
        ixz="3.0883652252364E-07"
        iyy="0.000213355266074738"
        iyz="-8.94550878113609E-07"
        izz="0.00125153113572145" />
    </inertial>
    <visual>
      <origin
        xyz="0 0 0"
        rpy="0 0 0" />
      <geometry>
        <mesh
          filename="package://nero_description/meshes/Link2.STL" />
      </geometry>
      <material
        name="">
        <color
          rgba="0.698039215686274 0.698039215686274 0.698039215686274 0.875" />
      </material>
    </visual>
    <collision>
      <origin
        xyz="0 0 0"
        rpy="0 0 0" />
      <geometry>
        <mesh
          filename="package://nero_description/meshes/Link2.STL" />
      </geometry>
    </collision>
  </link>
  <joint
    name="joint2"
    type="revolute">
    <origin
      xyz="0 0 0"
      rpy="1.5708 1.5708 0" />
    <parent
      link="Link1" />
    <child
      link="Link2" />
    <axis
      xyz="0 0 -1" />
    <limit
      lower="-0.2618"
      upper="3.3161"
      effort="100"
      velocity="10" />
  </joint>
  <link
    name="Link3">
    <inertial>
      <origin
        xyz="0.000329369340537011 0.000367393742880216 -0.0912010032043437"
        rpy="0 0 0" />
      <mass
        value="0.359899395208716" />
      <inertia
        ixx="0.000326426459526899"
        ixy="-7.9589690370858E-08"
        ixz="-3.20254640955194E-06"
        iyy="0.000359922429421077"
        iyz="-1.4226909768486E-06"
        izz="9.50921751679351E-05" />
    </inertial>
    <visual>
      <origin
        xyz="0 0 0"
        rpy="0 0 0" />
      <geometry>
        <mesh
          filename="package://nero_description/meshes/Link3.STL" />
      </geometry>
      <material
        name="">
        <color
          rgba="0.592156862745098 0.619607843137255 0.650980392156863 1" />
      </material>
    </visual>
    <collision>
      <origin
        xyz="0 0 0"
        rpy="0 0 0" />
      <geometry>
        <mesh
          filename="package://nero_description/meshes/Link3.STL" />
      </geometry>
    </collision>
  </link>
  <joint
    name="joint3"
    type="revolute">
    <origin
      xyz="0 -0.31 0"
      rpy="-1.5708 0 3.1416" />
    <parent
      link="Link2" />
    <child
      link="Link3" />
    <axis
      xyz="0 0 1" />
    <limit
      lower="-2.7925"
      upper="2.7925"
      effort="100"
      velocity="10" />
  </joint>
  <link
    name="Link4">
    <inertial>
      <origin
        xyz="-0.00090948139479044 -0.0503071433133058 0.00916295451944902"
        rpy="0 0 0" />
      <mass
        value="0.164135315169796" />
      <inertia
        ixx="0.000174183260832447"
        ixy="3.85077059441721E-06"
        ixz="-1.54723760900631E-07"
        iyy="6.55376510796343E-05"
        iyz="-2.08112584342887E-06"
        izz="0.000198941180189116" />
    </inertial>
    <visual>
      <origin
        xyz="0 0 0"
        rpy="0 0 0" />
      <geometry>
        <mesh
          filename="package://nero_description/meshes/Link4.STL" />
      </geometry>
      <material
        name="">
        <color
          rgba="0.592156862745098 0.619607843137255 0.650980392156863 1" />
      </material>
    </visual>
    <collision>
      <origin
        xyz="0 0 0"
        rpy="0 0 0" />
      <geometry>
        <mesh
          filename="package://nero_description/meshes/Link4.STL" />
      </geometry>
    </collision>
  </link>
  <joint
    name="joint4"
    type="revolute">
    <origin
      xyz="0 0 0"
      rpy="-1.5708 0 3.1416" />
    <parent
      link="Link3" />
    <child
      link="Link4" />
    <axis
      xyz="0 0 -1" />
    <limit
      lower="-1.0472"
      upper="2.1817"
      effort="100"
      velocity="10" />
  </joint>
  <link
    name="Link5">
    <inertial>
      <origin
        xyz="0.000247508903624559 -0.000503952827460075 -0.103181107893683"
        rpy="0 0 0" />
      <mass
        value="0.26290365411796" />
      <inertia
        ixx="0.000286471020887866"
        ixy="2.42735542088078E-07"
        ixz="-7.39872687538375E-07"
        iyy="0.000256499213556085"
        iyz="-2.34620347411223E-06"
        izz="8.48655617655643E-05" />
    </inertial>
    <visual>
      <origin
        xyz="0 0 0"
        rpy="0 0 0" />
      <geometry>
        <mesh
          filename="package://nero_description/meshes/Link5.STL" />
      </geometry>
      <material
        name="">
        <color
          rgba="0.592156862745098 0.619607843137255 0.650980392156863 1" />
      </material>
    </visual>
    <collision>
      <origin
        xyz="0 0 0"
        rpy="0 0 0" />
      <geometry>
        <mesh
          filename="package://nero_description/meshes/Link5.STL" />
      </geometry>
    </collision>
  </link>
  <joint
    name="joint5"
    type="revolute">
    <origin
      xyz="0 -0.27001 0"
      rpy="1.5708 -1.5708 0" />
    <parent
      link="Link4" />
    <child
      link="Link5" />
    <axis
      xyz="0 0 1" />
    <limit
      lower="-2.7925"
      upper="2.7925"
      effort="100"
      velocity="10" />
  </joint>
  <link
    name="Link6">
    <inertial>
      <origin
        xyz="7.76985979518141E-05 0.00155428293865652 -0.000196698394733047"
        rpy="0 0 0" />
      <mass
        value="0.0346374690978017" />
      <inertia
        ixx="5.41014573027983E-06"
        ixy="-2.53158407563903E-08"
        ixz="-5.77076135193377E-08"
        iyy="9.75643100389665E-06"
        iyz="3.4010295821093E-08"
        izz="5.56054302578999E-06" />
    </inertial>
    <visual>
      <origin
        xyz="0 0 0"
        rpy="0 0 0" />
      <geometry>
        <mesh
          filename="package://nero_description/meshes/Link6.STL" />
      </geometry>
      <material
        name="">
        <color
          rgba="1 1 1 1" />
      </material>
    </visual>
    <collision>
      <origin
        xyz="0 0 0"
        rpy="0 0 0" />
      <geometry>
        <mesh
          filename="package://nero_description/meshes/Link6.STL" />
      </geometry>
    </collision>
  </link>
  <joint
    name="joint6"
    type="revolute">
    <origin
      xyz="0 0 0"
      rpy="1.5708 -1.5708 0" />
    <parent
      link="Link5" />
    <child
      link="Link6" />
    <axis
      xyz="0 0 -1" />
    <limit
      lower="-0.7505"
      upper="1.0123"
      effort="100"
      velocity="10" />
  </joint>
  <link
    name="Link7">
    <inertial>
      <origin
        xyz="-0.000139607625717852 -0.000102022251390804 -0.00275209775972314"
        rpy="0 0 0" />
      <mass
        value="0.00232665325657446" />
      <inertia
        ixx="9.44277513776404E-08"
        ixy="-3.07406565085618E-24"
        ixz="-5.21148689611849E-10"
        iyy="9.44244711276097E-08"
        iyz="2.55388843335658E-22"
        izz="1.77221804908522E-07" />
    </inertial>
    <visual>
      <origin
        xyz="0 0 0"
        rpy="0 0 0" />
      <geometry>
        <mesh
          filename="package://nero_description/meshes/Link7.STL" />
      </geometry>
      <material
        name="">
        <color
          rgba="1 1 1 1" />
      </material>
    </visual>
    <collision>
      <origin
        xyz="0 0 0"
        rpy="0 0 0" />
      <geometry>
        <mesh
          filename="package://nero_description/meshes/Link7.STL" />
      </geometry>
    </collision>
  </link>
  <joint
    name="joint7"
    type="revolute">
    <origin
      xyz="0 -0.0235 0"
      rpy="1.5708 0 0" />
    <parent
      link="Link6" />
    <child
      link="Link7" />
    <axis
      xyz="0 0 1" />
    <limit
      lower="-1.57"
      upper="1.57"
      effort="100"
      velocity="10" />
  </joint>
</robot>